Workbook

Sheet READ ME
A1: FynHelp Tester Kit · READ ME FIRST
A2: One workbook, six sheets. Check in, do your tasks, log what you find, check out. About 2 to 3 hours a day.
B4: 1. YOUR DAY IN FIVE STEPS
B5: When | C5: Open this sheet | D5: Time | E5: What to do
B6: 1. Start of day | C6: Check-in | D6: 2 min | E6: Add one row: date, your name, start time, which Day of the plan you are on. Tick off your plan in Tasks.
B7: 2. Work | C7: Tasks | D7: 2 to 3 hours | E7: Do the tasks for today's Day, in order. Change Status as you go: Not started, In progress, Done, Blocked. Never leave a task untouched without a note.
B8: 3. Found something broken | C8: Bugs | D8: 3 to 5 min each | E8: One row per problem, filled straight away, with a screenshot. Pick a Severity.
B9: 4. Confusing, slow or ugly but it works | C9: UX Notes | D9: 2 min each | E9: Tell us what confused you and what you expected. These notes are as valuable as bugs.
B10: 5. End of day | C10: Check-out | D10: 5 min | E10: One row: end time, tasks done, what is left and why, one thing you learned, plan for tomorrow.
B11: Team lead only | C11: Dashboard | D11: - | E11: Live summary: task progress, bugs by severity, hours per tester. Testers only look, never type here.
B13: 2. BUG or UX NOTE? (ask yourself one question)
B14: If | C14: Use | D14: Examples
B15: It is WRONG or BROKEN | C15: Bugs | D15: A number is wrong, a button does nothing, a page crashes, a message is false, something you saved is gone. If a developer could fix it, it is a bug.
B16: It WORKS but feels bad | C16: UX Notes | D16: Confusing words, too many clicks, slow, hard to read on a phone, you did not know what to do next. Tell us what you expected.
B17: Not sure | C17: Bugs | D17: File it as a bug with Severity = Minor. Your lead will move it if needed. A wasted row costs nothing; a missed bug does.
B19: 3. COLOUR CODES (the same everywhere)
B20: Deep maroon, white text | C20: Column headings. Do not type here.
B21: Cream cell | C21: Your cell. Type here.
B22: Grey italic cell | C22: Fills itself in. Do not type here.
B23: Beige italic row | C23: An EXAMPLE row showing the format. Copy its style, then ignore it.
B24: Green | C24: Good: Done, Closed, Fixed, hours on target.
B25: Amber | C25: Needs attention: In progress, New bug, Minor, Medium impact, under 2 hours.
B26: Red | C26: Stuck or serious: Blocked, Reopened, High impact.
B27: Solid red, white text | C27: Severity MAJOR bug.
B28: Solid maroon, white text | C28: Severity BLOCKER bug. Tell your lead by message as well.
B29: Light grey | C29: Parked: Skipped, Duplicate, Cosmetic, Low impact.
B31: 4. SEVERITY: how bad is the bug?
B32: Severity | C32: In short | D32: Meaning and example
B33: Blocker | C33: Cannot continue | D33: You cannot go on, data is lost, a money figure is wrong, or something private is visible to the wrong person. Example: MIS revenue does not equal the transactions behind it.
B34: Major | C34: Feature fails | D34: The feature does not do what it says, but there is a way round. Example: Excel export is empty; PDF works.
B35: Minor | C35: Small glitch | D35: Works, but something is off. Example: wrong message after upload; a filter forgets your choice.
B36: Cosmetic | C36: Looks wrong | D36: Spelling, spacing, alignment, colour, a cut-off word.
B38: 5. A GOOD BUG IN 60 SECONDS
B39: 1. Where: the page or screen name, as the menu calls it (for example Documents). 2. Title: one line that says what is wrong. Good: "Upload shows 8 transactions, file has 7". Bad: "Upload broken". 3. Steps: numbered, short. Someone who has never seen the app must be able to repeat them. 4. Expected vs Actual: what should happen, and what did happen. Use real numbers. 5. Proof: a screenshot or a short screen recording. Save it in the shared folder, name it with the task ID (for example D2-02.png), paste the link. 6. Pick Severity from the dropdown. If you are unsure, pick one lower and say why in the title.
B41: 6. GOLDEN RULES
B42: • Use only the test site, the test account and the sample files from the /samples page. Never real client data. • Never connect a real Gmail, WhatsApp, Zoho or Tally account, never pay with a real card, never message a real person. • Update this sheet as you go, not at the end of the day. • One problem = one row. Do not bundle five issues into one. • Stuck for 15 minutes? Mark the task Blocked, write why in Notes, and message your lead. Then move to the next task. • Never delete a row. Wrong entry? Fix the cell, or mark a bug Duplicate. • Shared workbook: only edit your own rows. Cream cells only.
B44: 7. SET-UP (lead fills this once)
B45: Test site link | C45: Lead: paste the link here
B46: Test login / password | C46: Lead: paste here, or say where to find it
B47: Your team lead | C47: Lead: name and phone or chat
...

Sheet Check-in
A1: Check-in · start of day
A2: One row per tester per day. Takes 2 minutes. Do it before you open the app.
A4: Date | B4: Tester | C4: Start time | D4: Day of plan (1 to 5) | E4: Planned minutes (auto) | F4: Tasks I will do today (IDs) | G4: Device and browser | H4: Anything blocking me?
A5: EXAMPLE | B5: Asha | C5: 10:00 AM | D5: 2 | E5: (auto) | F5: D2-01 to D2-08 | G5: Windows laptop, Chrome | H5: None. Need the test password for the second account.
E6: =IF(D6="","",SUMIFS(Tasks!$G$5:$G$48,Tasks!$B$5:$B$48,D6))
E7: =IF(D7="","",SUMIFS(Tasks!$G$5:$G$48,Tasks!$B$5:$B$48,D7))
E8: =IF(D8="","",SUMIFS(Tasks!$G$5:$G$48,Tasks!$B$5:$B$48,D8))
E9: =IF(D9="","",SUMIFS(Tasks!$G$5:$G$48,Tasks!$B$5:$B$48,D9))
E10: =IF(D10="","",SUMIFS(Tasks!$G$5:$G$48,Tasks!$B$5:$B$48,D10))
E11: =IF(D11="","",SUMIFS(Tasks!$G$5:$G$48,Tasks!$B$5:$B$48,D11))
E12: =IF(D12="","",SUMIFS(Tasks!$G$5:$G$48,Tasks!$B$5:$B$48,D12))
E13: =IF(D13="","",SUMIFS(Tasks!$G$5:$G$48,Tasks!$B$5:$B$48,D13))
E14: =IF(D14="","",SUMIFS(Tasks!$G$5:$G$48,Tasks!$B$5:$B$48,D14))
E15: =IF(D15="","",SUMIFS(Tasks!$G$5:$G$48,Tasks!$B$5:$B$48,D15))
E16: =IF(D16="","",SUMIFS(Tasks!$G$5:$G$48,Tasks!$B$5:$B$48,D16))
E17: =IF(D17="","",SUMIFS(Tasks!$G$5:$G$48,Tasks!$B$5:$B$48,D17))
... E205: =IF(D205="","",SUMIFS(Tasks!$G$5:$G$48,Tasks!$B$5:$B$48,D205))

Sheet Tasks
A1: Tasks · Week 1
A2: Do today's Day in order. Change Status as you go. 'Min' is the time to budget, not a deadline. Each Day is about 2.5 hours.
A4: ID | B4: Day | C4: Task | D4: Where in the app | E4: How (steps) | F4: What should happen | G4: Min | H4: Status | I4: Done on | J4: Notes / Bug IDs
A5: D1-01 | B5: 1 | C5: Set up your toolkit | D5: This workbook + your browser | E5: 1. Read the READ ME tab once. 2. Type your name in READ ME > Team. 3. Install Chrome, bookmark the test site, make a folder called Screenshots. | F5: Your name shows in the Tester dropdown on every sheet | G5: 15 | H5: Not started
A6: D1-02 | B6: 1 | C6: Read the product guide | D6: Website > /guide | E6: Read the whole page once. Then add 3 lines to UX Notes: what FynHelp does, in your own words. | F6: You can explain it to a friend in 20 seconds | G6: 25 | H6: Not started
A7: D1-03 | B7: 1 | C7: Create your test account | D7: App > /app > Create account | E7: Sign up with your test email and a strong password. Sign out. Sign in again. Press Forgot password once. | F7: Every step works; every message is clear and in plain language | G7: 25 | H7: Not started
A8: D1-04 | B8: 1 | C8: Set up the firm and first client | D8: App > first-run steps 2 and 3 | E8: Enter a firm name. Add a client called Sundara Textiles Pvt Ltd. | F8: You reach the next step; the client appears under Clients | G8: 20 | H8: Not started
A9: D1-05 | B9: 1 | C9: Click every menu item | D9: App > left menu | E9: Open Portfolio, Clients, Documents, Review Queue, Exception Queue, Chaser, MIS and Reports, Settings. Write one line each in UX Notes: its name and what you think it is for. | F9: 8 screens noted; anything empty, broken or confusing is written down | G9: 30 | H9: Not started
A10: D1-06 | B10: 1 | C10: Practise filing a bug | D10: Bugs sheet | E10: Find ANY small thing (typo, odd wording, misalignment). Fill one full row in Bugs, with a screenshot link. | F10: Your lead can repeat your steps in under 2 minutes | G10: 25 | H10: Not started
A11: D1-07 | B11: 1 | C11: Phone check | D11: Your phone's browser | E11: Open the test site on your phone and sign in. Screenshot two screens. | F11: Text readable, no sideways scrolling | G11: 10 | H11: Not started
A12: D2-01 | B12: 2 | C12: Download the sample files | D12: Website > /samples | E12: Download the three September 2026 files into one folder: hdfc_statement_sep2026.csv, tally_daybook_sep2026.xml, purchase_register_sep2026.csv. | F12: 3 files saved | G12: 10 | H12: Not started
A13: D2-02 | B13: 2 | C13: Upload the bank statement | D13: App > Documents > Upload | E13: Set the period to September 2026. Upload hdfc_statement_sep2026.csv. Watch the status change. | F13: 7 transactions read; 1 line (the USD Stripe payout) goes to Review | G13: 20 | H13: Not started
A14: D2-03 | B14: 2 | C14: Upload the Tally day book | D14: App > Documents | E14: Upload tally_daybook_sep2026.xml. | F14: 6 transactions read; Recon starts on its own | G14: 15 | H14: Not started
A15: D2-04 | B15: 2 | C15: Check numbers against the file | D15: Documents + the CSV in Excel | E15: Open the CSV in Excel. Pick 3 lines. Compare date, amount and name with what the app shows. | F15: All 3 match exactly. Any difference is a bug. Closing balance on the statement is 4,86,484.30 | G15: 25 | H15: Not started
A16: D2-05 | B16: 2 | C16: Try bad uploads | D16: App > Documents > Upload | E16: Upload each: (a) the same CSV again, (b) an empty .txt file, (c) a photo (JPG), (d) a file over 25 MB if you can find one. | F16: (a) not added twice (b) clear message (c) read, or a friendly can't-read message (d) clear size message. No crash or blank screen | G16: 30 | H16: Not started
... A43: D5-07 | B43: 5 | C43: Week wrap-up | D43: UX Notes + Bugs | E43: Pick your top 5 findings. Put them in Check-out under 'One thing I learned'. Join the 10-minute wrap-up call. | F43: Lead knows your top 5 | G43: 20 | H43: Not started
A44: B-01 | B44: Bonus | C44: Break-it session | D44: Any one screen | E44: Spend 20 minutes entering odd things: emoji, very long text, only spaces, blank, negative numbers, a rupee sign. | F44: No crash; sensible messages | G44: 20 | H44: Not started
A45: B-02 | B45: Bonus | C45: Read the privacy page as a client | D45: Website > /privacy | E45: Note anything you would not understand if you were a shop owner. | F45: UX Notes filled | G45: 15 | H45: Not started
A46: B-03 | B46: Bonus | C46: Hindi and long names | D46: Clients > Add client | E46: Add a client named in Hindi, and one with a 100-letter name. | F46: Saved and shown correctly; no cut-off | G46: 15 | H46: Not started
A47: B-04 | B47: Bonus | C47: Slow internet | D47: Phone on mobile data, or browser throttling | E47: Repeat an upload on a slow connection. | F47: Clear progress or message; no silent failure | G47: 20 | H47: Not started
A48: B-05 | B48: Bonus | C48: The bigger July pack | D48: Website > /samples > July 2026 walkthrough | E48: Follow the July 2026 pack steps on the page with a new client. | F48: Results match the Expect lines on the page | G48: 30 | H48: Not started

Sheet Bugs
A1: Bugs · something is wrong or broken
A2: One problem per row, filled in the moment you see it. IDs fill themselves. Cream cells only; the last column is for your lead.
A4: ID (auto) | B4: Date | C4: Reporter | D4: Where (screen) | E4: One-line title | F4: Steps to reproduce (1, 2, 3) | G4: Expected | H4: Actual | I4: Severity | J4: Status | K4: Device and browser | L4: Screenshot or video link | M4: Lead's note
A5: EXAMPLE | B5: 21-Oct | C5: Asha | D5: Documents | E5: Upload shows 8 transactions, file has 7 | F5: 1. Documents > Upload 2. Choose hdfc_statement_sep2026.csv 3. Look at the result card | G5: 7 transactions read, 1 in Review | H5: Card says 8 transactions read | I5: Major | J5: New | K5: Windows, Chrome 130 | L5: link to D2-02.png
A6: =IF(E6="","","BUG-"&TEXT(ROW()-5,"000"))
A7: =IF(E7="","","BUG-"&TEXT(ROW()-5,"000"))
A8: =IF(E8="","","BUG-"&TEXT(ROW()-5,"000"))
A9: =IF(E9="","","BUG-"&TEXT(ROW()-5,"000"))
A10: =IF(E10="","","BUG-"&TEXT(ROW()-5,"000"))
A11: =IF(E11="","","BUG-"&TEXT(ROW()-5,"000"))
A12: =IF(E12="","","BUG-"&TEXT(ROW()-5,"000"))
A13: =IF(E13="","","BUG-"&TEXT(ROW()-5,"000"))
A14: =IF(E14="","","BUG-"&TEXT(ROW()-5,"000"))
A15: =IF(E15="","","BUG-"&TEXT(ROW()-5,"000"))
A16: =IF(E16="","","BUG-"&TEXT(ROW()-5,"000"))
A17: =IF(E17="","","BUG-"&TEXT(ROW()-5,"000"))
... A305: =IF(E305="","","BUG-"&TEXT(ROW()-5,"000"))

Sheet UX Notes
A1: UX Notes · it works, but it felt wrong
A2: Confusing words, too many clicks, slow, hard on a phone, unclear next step. Say what you expected. No judgement: these shape the product.
A4: Date | B4: Tester | C4: Screen | D4: What confused me or felt slow | E4: What I expected | F4: My idea (optional) | G4: Impact | H4: Lead's note
A5: EXAMPLE | B5: Asha | C5: Exception Queue | D5: I did not know what 'reconciled elsewhere' means. | E5: A one-line help text beside it. | F5: Add a small (?) with an example. | G5: Medium

Sheet Check-out
A1: Check-out · end of day
A2: One row per tester per day. Takes 5 minutes. Grey cells fill themselves from your other sheets.
A4: Date | B4: Tester | C4: Start (auto) | D4: End time | E4: Hours (auto) | F4: Tasks done today (IDs) | G4: Not finished, and why | H4: Bugs filed (auto) | I4: UX notes (auto) | J4: One thing I learned | K4: Plan for tomorrow | L4: Blockers for my lead
A5: EXAMPLE | B5: Asha | C5: 10:00 AM | D5: 1:00 PM | E5: 3 | F5: D2-01 to D2-07 | G5: D2-08 screenshots: ran out of time | H5: 2 | I5: 1 | J5: A duplicate upload is caught by the app, but the message is easy to miss. | K5: Day 3: Recon and MIS | L5: None
C6: =IF(OR(A6="",B6=""),"",IFERROR(1/(1/SUMIFS('Check-in'!$C$6:$C$205,'Check-in'!$A$6:$A$205,A6,'Check-in'!$B$6:$B$205,B6)),"")) | E6: =IF(OR(C6="",D6=""),"",ROUND((D6-C6)*24,1)) | H6: =IF(OR(A6="",B6=""),"",COUNTIFS(Bugs!$B$6:$B$305,A6,Bugs!$C$6:$C$305,B6)) | I6: =IF(OR(A6="",B6=""),"",COUNTIFS('UX Notes'!$A$6:$A$205,A6,'UX Notes'!$B$6:$B$205,B6))
C7: =IF(OR(A7="",B7=""),"",IFERROR(1/(1/SUMIFS('Check-in'!$C$6:$C$205,'Check-in'!$A$6:$A$205,A7,'Check-in'!$B$6:$B$205,B7)),"")) | E7: =IF(OR(C7="",D7=""),"",ROUND((D7-C7)*24,1)) | H7: =IF(OR(A7="",B7=""),"",COUNTIFS(Bugs!$B$6:$B$305,A7,Bugs!$C$6:$C$305,B7)) | I7: =IF(OR(A7="",B7=""),"",COUNTIFS('UX Notes'!$A$6:$A$205,A7,'UX Notes'!$B$6:$B$205,B7))
C8: =IF(OR(A8="",B8=""),"",IFERROR(1/(1/SUMIFS('Check-in'!$C$6:$C$205,'Check-in'!$A$6:$A$205,A8,'Check-in'!$B$6:$B$205,B8)),"")) | E8: =IF(OR(C8="",D8=""),"",ROUND((D8-C8)*24,1)) | H8: =IF(OR(A8="",B8=""),"",COUNTIFS(Bugs!$B$6:$B$305,A8,Bugs!$C$6:$C$305,B8)) | I8: =IF(OR(A8="",B8=""),"",COUNTIFS('UX Notes'!$A$6:$A$205,A8,'UX Notes'!$B$6:$B$205,B8))
C9: =IF(OR(A9="",B9=""),"",IFERROR(1/(1/SUMIFS('Check-in'!$C$6:$C$205,'Check-in'!$A$6:$A$205,A9,'Check-in'!$B$6:$B$205,B9)),"")) | E9: =IF(OR(C9="",D9=""),"",ROUND((D9-C9)*24,1)) | H9: =IF(OR(A9="",B9=""),"",COUNTIFS(Bugs!$B$6:$B$305,A9,Bugs!$C$6:$C$305,B9)) | I9: =IF(OR(A9="",B9=""),"",COUNTIFS('UX Notes'!$A$6:$A$205,A9,'UX Notes'!$B$6:$B$205,B9))
C10: =IF(OR(A10="",B10=""),"",IFERROR(1/(1/SUMIFS('Check-in'!$C$6:$C$205,'Check-in'!$A$6:$A$205,A10,'Check-in'!$B$6:$B$205,B10)),"")) | E10: =IF(OR(C10="",D10=""),"",ROUND((D10-C10)*24,1)) | H10: =IF(OR(A10="",B10=""),"",COUNTIFS(Bugs!$B$6:$B$305,A10,Bugs!$C$6:$C$305,B10)) | I10: =IF(OR(A10="",B10=""),"",COUNTIFS('UX Notes'!$A$6:$A$205,A10,'UX Notes'!$B$6:$B$205,B10))
C11: =IF(OR(A11="",B11=""),"",IFERROR(1/(1/SUMIFS('Check-in'!$C$6:$C$205,'Check-in'!$A$6:$A$205,A11,'Check-in'!$B$6:$B$205,B11)),"")) | E11: =IF(OR(C11="",D11=""),"",ROUND((D11-C11)*24,1)) | H11: =IF(OR(A11="",B11=""),"",COUNTIFS(Bugs!$B$6:$B$305,A11,Bugs!$C$6:$C$305,B11)) | I11: =IF(OR(A11="",B11=""),"",COUNTIFS('UX Notes'!$A$6:$A$205,A11,'UX Notes'!$B$6:$B$205,B11))
C12: =IF(OR(A12="",B12=""),"",IFERROR(1/(1/SUMIFS('Check-in'!$C$6:$C$205,'Check-in'!$A$6:$A$205,A12,'Check-in'!$B$6:$B$205,B12)),"")) | E12: =IF(OR(C12="",D12=""),"",ROUND((D12-C12)*24,1)) | H12: =IF(OR(A12="",B12=""),"",COUNTIFS(Bugs!$B$6:$B$305,A12,Bugs!$C$6:$C$305,B12)) | I12: =IF(OR(A12="",B12=""),"",COUNTIFS('UX Notes'!$A$6:$A$205,A12,'UX Notes'!$B$6:$B$205,B12))
C13: =IF(OR(A13="",B13=""),"",IFERROR(1/(1/SUMIFS('Check-in'!$C$6:$C$205,'Check-in'!$A$6:$A$205,A13,'Check-in'!$B$6:$B$205,B13)),"")) | E13: =IF(OR(C13="",D13=""),"",ROUND((D13-C13)*24,1)) | H13: =IF(OR(A13="",B13=""),"",COUNTIFS(Bugs!$B$6:$B$305,A13,Bugs!$C$6:$C$305,B13)) | I13: =IF(OR(A13="",B13=""),"",COUNTIFS('UX Notes'!$A$6:$A$205,A13,'UX Notes'!$B$6:$B$205,B13))
C14: =IF(OR(A14="",B14=""),"",IFERROR(1/(1/SUMIFS('Check-in'!$C$6:$C$205,'Check-in'!$A$6:$A$205,A14,'Check-in'!$B$6:$B$205,B14)),"")) | E14: =IF(OR(C14="",D14=""),"",ROUND((D14-C14)*24,1)) | H14: =IF(OR(A14="",B14=""),"",COUNTIFS(Bugs!$B$6:$B$305,A14,Bugs!$C$6:$C$305,B14)) | I14: =IF(OR(A14="",B14=""),"",COUNTIFS('UX Notes'!$A$6:$A$205,A14,'UX Notes'!$B$6:$B$205,B14))
C15: =IF(OR(A15="",B15=""),"",IFERROR(1/(1/SUMIFS('Check-in'!$C$6:$C$205,'Check-in'!$A$6:$A$205,A15,'Check-in'!$B$6:$B$205,B15)),"")) | E15: =IF(OR(C15="",D15=""),"",ROUND((D15-C15)*24,1)) | H15: =IF(OR(A15="",B15=""),"",COUNTIFS(Bugs!$B$6:$B$305,A15,Bugs!$C$6:$C$305,B15)) | I15: =IF(OR(A15="",B15=""),"",COUNTIFS('UX Notes'!$A$6:$A$205,A15,'UX Notes'!$B$6:$B$205,B15))
C16: =IF(OR(A16="",B16=""),"",IFERROR(1/(1/SUMIFS('Check-in'!$C$6:$C$205,'Check-in'!$A$6:$A$205,A16,'Check-in'!$B$6:$B$205,B16)),"")) | E16: =IF(OR(C16="",D16=""),"",ROUND((D16-C16)*24,1)) | H16: =IF(OR(A16="",B16=""),"",COUNTIFS(Bugs!$B$6:$B$305,A16,Bugs!$C$6:$C$305,B16)) | I16: =IF(OR(A16="",B16=""),"",COUNTIFS('UX Notes'!$A$6:$A$205,A16,'UX Notes'!$B$6:$B$205,B16))
C17: =IF(OR(A17="",B17=""),"",IFERROR(1/(1/SUMIFS('Check-in'!$C$6:$C$205,'Check-in'!$A$6:$A$205,A17,'Check-in'!$B$6:$B$205,B17)),"")) | E17: =IF(OR(C17="",D17=""),"",ROUND((D17-C17)*24,1)) | H17: =IF(OR(A17="",B17=""),"",COUNTIFS(Bugs!$B$6:$B$305,A17,Bugs!$C$6:$C$305,B17)) | I17: =IF(OR(A17="",B17=""),"",COUNTIFS('UX Notes'!$A$6:$A$205,A17,'UX Notes'!$B$6:$B$205,B17))
... C205: =IF(OR(A205="",B205=""),"",IFERROR(1/(1/SUMIFS('Check-in'!$C$6:$C$205,'Check-in'!$A$6:$A$205,A205,'Check-in'!$B$6:$B$205,B205)),"")) | E205: =IF(OR(C205="",D205=""),"",ROUND((D205-C205)*24,1)) | H205: =IF(OR(A205="",B205=""),"",COUNTIFS(Bugs!$B$6:$B$305,A205,Bugs!$C$6:$C$305,B205)) | I205: =IF(OR(A205="",B205=""),"",COUNTIFS('UX Notes'!$A$6:$A$205,A205,'UX Notes'!$B$6:$B$205,B205))

Sheet Dashboard
A1: Dashboard · for the team lead
A2: Everything here is calculated. Testers: look, do not type. Colours follow the same rules as the other sheets.
A4: 1. Task progress by day
A5: Day | B5: Tasks | C5: Done | D5: Blocked | E5: Planned min | F5: Done min | G5: % done
A6: 1 | B6: =COUNTIFS(Tasks!$B$5:$B$48,$A6) -> 7 | C6: =COUNTIFS(Tasks!$B$5:$B$48,$A6,Tasks!$H$5:$H$48,"Done") -> 0 | D6: =COUNTIFS(Tasks!$B$5:$B$48,$A6,Tasks!$H$5:$H$48,"Blocked") -> 0 | E6: =SUMIFS(Tasks!$G$5:$G$48,Tasks!$B$5:$B$48,$A6) -> 150 | F6: =SUMIFS(Tasks!$G$5:$G$48,Tasks!$B$5:$B$48,$A6,Tasks!$H$5:$H$48,"Done") -> 0 | G6: =IFERROR(C6/B6,0) -> 0
A7: 2 | B7: =COUNTIFS(Tasks!$B$5:$B$48,$A7) -> 8 | C7: =COUNTIFS(Tasks!$B$5:$B$48,$A7,Tasks!$H$5:$H$48,"Done") -> 0 | D7: =COUNTIFS(Tasks!$B$5:$B$48,$A7,Tasks!$H$5:$H$48,"Blocked") -> 0 | E7: =SUMIFS(Tasks!$G$5:$G$48,Tasks!$B$5:$B$48,$A7) -> 150 | F7: =SUMIFS(Tasks!$G$5:$G$48,Tasks!$B$5:$B$48,$A7,Tasks!$H$5:$H$48,"Done") -> 0 | G7: =IFERROR(C7/B7,0) -> 0
A8: 3 | B8: =COUNTIFS(Tasks!$B$5:$B$48,$A8) -> 8 | C8: =COUNTIFS(Tasks!$B$5:$B$48,$A8,Tasks!$H$5:$H$48,"Done") -> 0 | D8: =COUNTIFS(Tasks!$B$5:$B$48,$A8,Tasks!$H$5:$H$48,"Blocked") -> 0 | E8: =SUMIFS(Tasks!$G$5:$G$48,Tasks!$B$5:$B$48,$A8) -> 165 | F8: =SUMIFS(Tasks!$G$5:$G$48,Tasks!$B$5:$B$48,$A8,Tasks!$H$5:$H$48,"Done") -> 0 | G8: =IFERROR(C8/B8,0) -> 0
A9: 4 | B9: =COUNTIFS(Tasks!$B$5:$B$48,$A9) -> 9 | C9: =COUNTIFS(Tasks!$B$5:$B$48,$A9,Tasks!$H$5:$H$48,"Done") -> 0 | D9: =COUNTIFS(Tasks!$B$5:$B$48,$A9,Tasks!$H$5:$H$48,"Blocked") -> 0 | E9: =SUMIFS(Tasks!$G$5:$G$48,Tasks!$B$5:$B$48,$A9) -> 150 | F9: =SUMIFS(Tasks!$G$5:$G$48,Tasks!$B$5:$B$48,$A9,Tasks!$H$5:$H$48,"Done") -> 0 | G9: =IFERROR(C9/B9,0) -> 0
A10: 5 | B10: =COUNTIFS(Tasks!$B$5:$B$48,$A10) -> 7 | C10: =COUNTIFS(Tasks!$B$5:$B$48,$A10,Tasks!$H$5:$H$48,"Done") -> 0 | D10: =COUNTIFS(Tasks!$B$5:$B$48,$A10,Tasks!$H$5:$H$48,"Blocked") -> 0 | E10: =SUMIFS(Tasks!$G$5:$G$48,Tasks!$B$5:$B$48,$A10) -> 150 | F10: =SUMIFS(Tasks!$G$5:$G$48,Tasks!$B$5:$B$48,$A10,Tasks!$H$5:$H$48,"Done") -> 0 | G10: =IFERROR(C10/B10,0) -> 0
A11: Days 1 to 5 total | B11: =SUM(B6:B10) -> 39 | C11: =SUM(C6:C10) -> 0 | D11: =SUM(D6:D10) -> 0 | E11: =SUM(E6:E10) -> 765 | F11: =SUM(F6:F10) -> 0 | G11: =IFERROR(C11/B11,0) -> 0
A12: Bonus | B12: =COUNTIFS(Tasks!$B$5:$B$48,$A12) -> 5 | C12: =COUNTIFS(Tasks!$B$5:$B$48,$A12,Tasks!$H$5:$H$48,"Done") -> 0 | D12: =COUNTIFS(Tasks!$B$5:$B$48,$A12,Tasks!$H$5:$H$48,"Blocked") -> 0 | E12: =SUMIFS(Tasks!$G$5:$G$48,Tasks!$B$5:$B$48,$A12) -> 100 | F12: =SUMIFS(Tasks!$G$5:$G$48,Tasks!$B$5:$B$48,$A12,Tasks!$H$5:$H$48,"Done") -> 0 | G12: =IFERROR(C12/B12,0) -> 0
A14: 2. Bugs: severity by status
A15: Severity | B15: New | C15: Seen | D15: Fixed | E15: Closed | F15: Reopened | G15: Duplicate | H15: Total
A16: Blocker | B16: =COUNTIFS(Bugs!$I$6:$I$305,$A16,Bugs!$J$6:$J$305,"New") -> 0 | C16: =COUNTIFS(Bugs!$I$6:$I$305,$A16,Bugs!$J$6:$J$305,"Seen") -> 0 | D16: =COUNTIFS(Bugs!$I$6:$I$305,$A16,Bugs!$J$6:$J$305,"Fixed") -> 0 | E16: =COUNTIFS(Bugs!$I$6:$I$305,$A16,Bugs!$J$6:$J$305,"Closed") -> 0 | F16: =COUNTIFS(Bugs!$I$6:$I$305,$A16,Bugs!$J$6:$J$305,"Reopened") -> 0 | G16: =COUNTIFS(Bugs!$I$6:$I$305,$A16,Bugs!$J$6:$J$305,"Duplicate") -> 0 | H16: =SUM(B16:G16) -> 0
A17: Major | B17: =COUNTIFS(Bugs!$I$6:$I$305,$A17,Bugs!$J$6:$J$305,"New") -> 0 | C17: =COUNTIFS(Bugs!$I$6:$I$305,$A17,Bugs!$J$6:$J$305,"Seen") -> 0 | D17: =COUNTIFS(Bugs!$I$6:$I$305,$A17,Bugs!$J$6:$J$305,"Fixed") -> 0 | E17: =COUNTIFS(Bugs!$I$6:$I$305,$A17,Bugs!$J$6:$J$305,"Closed") -> 0 | F17: =COUNTIFS(Bugs!$I$6:$I$305,$A17,Bugs!$J$6:$J$305,"Reopened") -> 0 | G17: =COUNTIFS(Bugs!$I$6:$I$305,$A17,Bugs!$J$6:$J$305,"Duplicate") -> 0 | H17: =SUM(B17:G17) -> 0
A18: Minor | B18: =COUNTIFS(Bugs!$I$6:$I$305,$A18,Bugs!$J$6:$J$305,"New") -> 0 | C18: =COUNTIFS(Bugs!$I$6:$I$305,$A18,Bugs!$J$6:$J$305,"Seen") -> 0 | D18: =COUNTIFS(Bugs!$I$6:$I$305,$A18,Bugs!$J$6:$J$305,"Fixed") -> 0 | E18: =COUNTIFS(Bugs!$I$6:$I$305,$A18,Bugs!$J$6:$J$305,"Closed") -> 0 | F18: =COUNTIFS(Bugs!$I$6:$I$305,$A18,Bugs!$J$6:$J$305,"Reopened") -> 0 | G18: =COUNTIFS(Bugs!$I$6:$I$305,$A18,Bugs!$J$6:$J$305,"Duplicate") -> 0 | H18: =SUM(B18:G18) -> 0
A19: Cosmetic | B19: =COUNTIFS(Bugs!$I$6:$I$305,$A19,Bugs!$J$6:$J$305,"New") -> 0 | C19: =COUNTIFS(Bugs!$I$6:$I$305,$A19,Bugs!$J$6:$J$305,"Seen") -> 0 | D19: =COUNTIFS(Bugs!$I$6:$I$305,$A19,Bugs!$J$6:$J$305,"Fixed") -> 0 | E19: =COUNTIFS(Bugs!$I$6:$I$305,$A19,Bugs!$J$6:$J$305,"Closed") -> 0 | F19: =COUNTIFS(Bugs!$I$6:$I$305,$A19,Bugs!$J$6:$J$305,"Reopened") -> 0 | G19: =COUNTIFS(Bugs!$I$6:$I$305,$A19,Bugs!$J$6:$J$305,"Duplicate") -> 0 | H19: =SUM(B19:G19) -> 0
A20: All | B20: =SUM(B16:B19) -> 0 | C20: =SUM(C16:C19) -> 0 | D20: =SUM(D16:D19) -> 0 | E20: =SUM(E16:E19) -> 0 | F20: =SUM(F16:F19) -> 0 | G20: =SUM(G16:G19) -> 0 | H20: =SUM(H16:H19) -> 0
A21: Red = Blocker or Major bugs still New, or any bug Reopened. These need a human today.
A23: 3. Per tester
A24: Tester | B24: Check-ins | C24: Check-outs | D24: Hours | E24: Bugs | F24: Blocker / Major | G24: UX notes | H24: Tasks done
A25: =IF('READ ME'!$C$51="","",'READ ME'!$C$51) -> Asha (example) | B25: =IF($A25="","",COUNTIFS('Check-in'!$B$6:$B$205,$A25)) -> 0 | C25: =IF($A25="","",COUNTIFS('Check-out'!$B$6:$B$205,$A25)) -> 0 | D25: =IF($A25="","",SUMIFS('Check-out'!$E$6:$E$205,'Check-out'!$B$6:$B$205,$A25)) -> 0 | E25: =IF($A25="","",COUNTIFS(Bugs!$C$6:$C$305,$A25)) -> 0 | F25: =IF($A25="","",COUNTIFS(Bugs!$C$6:$C$305,$A25,Bugs!$I$6:$I$305,"Blocker")+COUNTIFS(Bugs!$C$6:$C$305,$A25,Bugs!$I$6:$I$305,"Major")) -> 0 | G25: =IF($A25="","",COUNTIFS('UX Notes'!$B$6:$B$205,$A25)) -> 0 | H25: =IF($A25="","",COUNTIFS(Tasks!$J$5:$J$48,"*"&$A25&"*",Tasks!$H$5:$H$48,"Done")) -> 0
A26: =IF('READ ME'!$C$52="","",'READ ME'!$C$52) -> Rahul (example) | B26: =IF($A26="","",COUNTIFS('Check-in'!$B$6:$B$205,$A26)) -> 0 | C26: =IF($A26="","",COUNTIFS('Check-out'!$B$6:$B$205,$A26)) -> 0 | D26: =IF($A26="","",SUMIFS('Check-out'!$E$6:$E$205,'Check-out'!$B$6:$B$205,$A26)) -> 0 | E26: =IF($A26="","",COUNTIFS(Bugs!$C$6:$C$305,$A26)) -> 0 | F26: =IF($A26="","",COUNTIFS(Bugs!$C$6:$C$305,$A26,Bugs!$I$6:$I$305,"Blocker")+COUNTIFS(Bugs!$C$6:$C$305,$A26,Bugs!$I$6:$I$305,"Major")) -> 0 | G26: =IF($A26="","",COUNTIFS('UX Notes'!$B$6:$B$205,$A26)) -> 0 | H26: =IF($A26="","",COUNTIFS(Tasks!$J$5:$J$48,"*"&$A26&"*",Tasks!$H$5:$H$48,"Done")) -> 0
A27: =IF('READ ME'!$C$53="","",'READ ME'!$C$53) | B27: =IF($A27="","",COUNTIFS('Check-in'!$B$6:$B$205,$A27)) | C27: =IF($A27="","",COUNTIFS('Check-out'!$B$6:$B$205,$A27)) | D27: =IF($A27="","",SUMIFS('Check-out'!$E$6:$E$205,'Check-out'!$B$6:$B$205,$A27)) | E27: =IF($A27="","",COUNTIFS(Bugs!$C$6:$C$305,$A27)) | F27: =IF($A27="","",COUNTIFS(Bugs!$C$6:$C$305,$A27,Bugs!$I$6:$I$305,"Blocker")+COUNTIFS(Bugs!$C$6:$C$305,$A27,Bugs!$I$6:$I$305,"Major")) | G27: =IF($A27="","",COUNTIFS('UX Notes'!$B$6:$B$205,$A27)) | H27: =IF($A27="","",COUNTIFS(Tasks!$J$5:$J$48,"*"&$A27&"*",Tasks!$H$5:$H$48,"Done"))
A28: =IF('READ ME'!$C$54="","",'READ ME'!$C$54) | B28: =IF($A28="","",COUNTIFS('Check-in'!$B$6:$B$205,$A28)) | C28: =IF($A28="","",COUNTIFS('Check-out'!$B$6:$B$205,$A28)) | D28: =IF($A28="","",SUMIFS('Check-out'!$E$6:$E$205,'Check-out'!$B$6:$B$205,$A28)) | E28: =IF($A28="","",COUNTIFS(Bugs!$C$6:$C$305,$A28)) | F28: =IF($A28="","",COUNTIFS(Bugs!$C$6:$C$305,$A28,Bugs!$I$6:$I$305,"Blocker")+COUNTIFS(Bugs!$C$6:$C$305,$A28,Bugs!$I$6:$I$305,"Major")) | G28: =IF($A28="","",COUNTIFS('UX Notes'!$B$6:$B$205,$A28)) | H28: =IF($A28="","",COUNTIFS(Tasks!$J$5:$J$48,"*"&$A28&"*",Tasks!$H$5:$H$48,"Done"))
A29: =IF('READ ME'!$C$55="","",'READ ME'!$C$55) | B29: =IF($A29="","",COUNTIFS('Check-in'!$B$6:$B$205,$A29)) | C29: =IF($A29="","",COUNTIFS('Check-out'!$B$6:$B$205,$A29)) | D29: =IF($A29="","",SUMIFS('Check-out'!$E$6:$E$205,'Check-out'!$B$6:$B$205,$A29)) | E29: =IF($A29="","",COUNTIFS(Bugs!$C$6:$C$305,$A29)) | F29: =IF($A29="","",COUNTIFS(Bugs!$C$6:$C$305,$A29,Bugs!$I$6:$I$305,"Blocker")+COUNTIFS(Bugs!$C$6:$C$305,$A29,Bugs!$I$6:$I$305,"Major")) | G29: =IF($A29="","",COUNTIFS('UX Notes'!$B$6:$B$205,$A29)) | H29: =IF($A29="","",COUNTIFS(Tasks!$J$5:$J$48,"*"&$A29&"*",Tasks!$H$5:$H$48,"Done"))
A30: =IF('READ ME'!$C$56="","",'READ ME'!$C$56) | B30: =IF($A30="","",COUNTIFS('Check-in'!$B$6:$B$205,$A30)) | C30: =IF($A30="","",COUNTIFS('Check-out'!$B$6:$B$205,$A30)) | D30: =IF($A30="","",SUMIFS('Check-out'!$E$6:$E$205,'Check-out'!$B$6:$B$205,$A30)) | E30: =IF($A30="","",COUNTIFS(Bugs!$C$6:$C$305,$A30)) | F30: =IF($A30="","",COUNTIFS(Bugs!$C$6:$C$305,$A30,Bugs!$I$6:$I$305,"Blocker")+COUNTIFS(Bugs!$C$6:$C$305,$A30,Bugs!$I$6:$I$305,"Major")) | G30: =IF($A30="","",COUNTIFS('UX Notes'!$B$6:$B$205,$A30)) | H30: =IF($A30="","",COUNTIFS(Tasks!$J$5:$J$48,"*"&$A30&"*",Tasks!$H$5:$H$48,"Done"))
A31: =IF('READ ME'!$C$57="","",'READ ME'!$C$57) | B31: =IF($A31="","",COUNTIFS('Check-in'!$B$6:$B$205,$A31)) | C31: =IF($A31="","",COUNTIFS('Check-out'!$B$6:$B$205,$A31)) | D31: =IF($A31="","",SUMIFS('Check-out'!$E$6:$E$205,'Check-out'!$B$6:$B$205,$A31)) | E31: =IF($A31="","",COUNTIFS(Bugs!$C$6:$C$305,$A31)) | F31: =IF($A31="","",COUNTIFS(Bugs!$C$6:$C$305,$A31,Bugs!$I$6:$I$305,"Blocker")+COUNTIFS(Bugs!$C$6:$C$305,$A31,Bugs!$I$6:$I$305,"Major")) | G31: =IF($A31="","",COUNTIFS('UX Notes'!$B$6:$B$205,$A31)) | H31: =IF($A31="","",COUNTIFS(Tasks!$J$5:$J$48,"*"&$A31&"*",Tasks!$H$5:$H$48,"Done"))
A32: =IF('READ ME'!$C$58="","",'READ ME'!$C$58) | B32: =IF($A32="","",COUNTIFS('Check-in'!$B$6:$B$205,$A32)) | C32: =IF($A32="","",COUNTIFS('Check-out'!$B$6:$B$205,$A32)) | D32: =IF($A32="","",SUMIFS('Check-out'!$E$6:$E$205,'Check-out'!$B$6:$B$205,$A32)) | E32: =IF($A32="","",COUNTIFS(Bugs!$C$6:$C$305,$A32)) | F32: =IF($A32="","",COUNTIFS(Bugs!$C$6:$C$305,$A32,Bugs!$I$6:$I$305,"Blocker")+COUNTIFS(Bugs!$C$6:$C$305,$A32,Bugs!$I$6:$I$305,"Major")) | G32: =IF($A32="","",COUNTIFS('UX Notes'!$B$6:$B$205,$A32)) | H32: =IF($A32="","",COUNTIFS(Tasks!$J$5:$J$48,"*"&$A32&"*",Tasks!$H$5:$H$48,"Done"))
A33: Amber on check-ins or check-outs = a day was checked in but not out (or the other way round). Tasks done counts a tester's name written in the task's Notes column.

Sheet Lists
A1: Task status | B1: Severity | C1: Bug status | D1: Impact | E1: Day
A2: Not started | B2: Blocker | C2: New | D2: High | E2: 1
A3: In progress | B3: Major | C3: Seen | D3: Medium | E3: 2
A4: Done | B4: Minor | C4: Fixed | D4: Low | E4: 3
A5: Blocked | B5: Cosmetic | C5: Closed | E5: 4
A6: Skipped | C6: Reopened | E6: 5
C7: Duplicate
